<?xml version="1.0"?>
<robot xmlns:xacro="http://www.ros.org/wiki/xacro" name="rover">

<xacro:property name="constant" value="0.083"/>
<xacro:property name="mass" value="1.0"/>
<xacro:property name="width" value="0.9"/>
<xacro:property name="height" value="0.22"/>
<xacro:property name="depth" value="0.7"/>

<material name="purple">
        <color rgba="0.8 0.4 0.8 1.0"/>
</material>

<material name="black">
        <color rgba="0 0 0 1"/>
</material>

<link name="base_footprint"/>

<link name="base_link">
    <inertial>
        <origin xyz="0.0 0.0 0.0" rpy="1.57 0.0 0.0"/>
        <mass value="1.0"/>
        <inertia ixx="${constant * mass * (height * height + depth * depth)}" ixy="0.0" ixz="0.0"
                 iyy="${constant * mass * (width * width + depth * depth)}" iyz="0.0"
                 izz="${constant * mass * (width * width + height * height)}"/>
    </inertial>
    <visual name="">
        <origin xyz="0.0 0.0 0.06" rpy="0.0 0.0 0.0"/>
        <geometry>
            <box size="0.9 0.7 0.22"/>
        </geometry>
        <material name="purple"/>
    </visual>
    <collision>
        <origin xyz="0.0 0.0 0.06" rpy="0.0 0.0 0.0"/>
        <geometry>
            <box size="0.9 0.7 0.22"/>
        </geometry>
    </collision>
</link>

<gazebo reference="base_link">
    <material>Gazebo/Purple</material>
</gazebo>

<joint name="base_joint" type="fixed">
    <origin xyz="0.0 0.0 0.135" rpy="0.0 0.0 0.0"/>
    <parent link="base_footprint"/>
    <child link="base_link"/>
    <axis xyz="0.0 0.0 0.0"/>
</joint>

<!-- All Wheel links and joints -->


<xacro:macro name="wheel_l" params="name x y">

    <link name="wheel_${name}_link">
        <inertial>
            <origin xyz="0 0 0" />
            <mass value="0.1" />
            <inertia ixx="${0.083 * 0.1 * (3 * 0.165 * 0.165 + 0.09 * 0.09)}" ixy="0.0" ixz="0.0"
                    iyy="${0.083 * 0.1 * (3 * 0.165 * 0.165 + 0.09 * 0.09)}" iyz="0.0"
                    izz="${0.083 * 0.1 * 0.165 * 0.165}" />
        </inertial>
        <visual name="">
            <origin xyz="0.0 0.0 0.0" rpy="0.0 0.0 0.0"/>
            <geometry>
                <mesh filename="package://mobile_robot/meshes/left_tire.stl" scale="0.005 0.005 0.005"/>
            </geometry>
            <material name="black"/>
        </visual>
        <collision>
            <origin xyz="0 0 0" rpy="1.57 0 0"/>
            <geometry>
                <cylinder length="0.09" radius="0.165"/>
            </geometry>
        </collision>
    </link>

    <joint name="wheel_${name}_joint" type="continuous">
        <origin xyz="${x} ${y} .0" rpy="0 0.0 0.0"/>
        <parent link="base_link"/>
        <child link="wheel_${name}_link"/>
        <axis xyz=".0 1.0 .0"/>
    </joint>

</xacro:macro>

<xacro:macro name="wheel_r" params="name x y">

    <link name="wheel_${name}_link">
        <inertial>
            <origin xyz="0 0 0" />
            <mass value="0.1" />
            <inertia ixx="${0.083 * 0.1 * (3 * 0.165 * 0.165 + 0.09 * 0.09)}" ixy="0.0" ixz="0.0"
                    iyy="${0.083 * 0.1 * (3 * 0.165 * 0.165 + 0.09 * 0.09)}" iyz="0.0"
                    izz="${0.083 * 0.1 * 0.165 * 0.165}" />
        </inertial>
        <visual name="">
            <origin xyz="0.0 0.0 0.0" rpy="0.0 0.0 0.0"/>
            <geometry>
                <mesh filename="package://mobile_robot/meshes/right_tire.stl" scale="0.005 0.005 0.005"/>
            </geometry>
            <material name="black"/>
        </visual>
        <collision>
            <origin xyz="0 0 0" rpy="1.57 0 0"/>
            <geometry>
                <cylinder length="0.09" radius="0.165"/>
            </geometry>
        </collision>
    </link>

    <joint name="wheel_${name}_joint" type="continuous">
        <origin xyz="${x} ${y} .0" rpy="0 0.0 0.0"/>
        <parent link="base_link"/>
        <child link="wheel_${name}_link"/>
        <axis xyz=".0 1.0 .0"/>
    </joint>

</xacro:macro>


<!-- Wheel Creating using macros -->
<xacro:wheel_r name="rear_right"  x="0.3" y =" 0.40"/>
<xacro:wheel_r name="front_right" x="-0.3" y =" 0.40"/>
<xacro:wheel_l name="front_left"  x="-0.3" y =" -0.40"/>
<xacro:wheel_l name="rear_left"   x="0.3" y =" -0.40"/>



</robot>